Workbook

Sheet README
A1: NVDA Signal Workbook v3
A3: Purpose | B3: Workbook to organise raw inputs, scenario controls, synthetic raw paths, and derived state layers for testing the NVDA desk framework. | D3: Legend
A4: Scope | B4: Workbook now separates raw primitives from derived features, preserves explicit options-chain raw capture policy, and records Gate 41-44 playbook/module audit outcomes. | D4: Blue text | E4: User input / scenario control
A5: Workflow | B5: 1) Adjust Controls / Scenario. 2) Review Synthetic_Raw. 3) Inspect derived tabs. 4) Use scenario packs for replay / regression tests. | D5: Black text | E5: Formula or calculated output
A6: Data philosophy | B6: 1) Review Live_Web_Baseline. 2) Check web-seeded Anchor_Data. 3) Adjust Controls / Scenario. 4) Inspect Synthetic_Raw and derived tabs. | D6: Gray text | E6: Static note / taxonomy
B7: Live web snapshot for ballpark baseline + synthetic regime-conditioned expansion. Raw first, derived second. | D7: Orange fill | E7: Review / caution
A8: Core sheet order | D8: Teal fill | E8: Key KPI / scenario driver
A9: 1 | B9: Controls
A10: 2 | B10: Scenario_Packs | D10: Added | E10: Temporal Step1 sheets separate clock/calendar, primitive intraday observables, and a 30-second test harness.
A11: 3 | B11: Raw_Catalog | D11: Design rule | E11: Step 1 may reuse primitives later, but may not consume Step 2/3 derived outputs.
A12: 4 | B12: Anchor_Data
A13: 5 | B13: Synthetic_Raw
A14: 6 | B14: Derived_Beta_Leadership
A15: 7 | B15: Derived_Vol_Rates_FX
A16: 8 | B16: Derived_Execution_Options
A17: 9 | B17: Derived_Asia_Breadth
A18: 10 | B18: Test_Use_Cases
A19: 11 | B19: Temporal_Step1_Framework
A20: 12 | B20: Temporal_Step1_Tests
A22: 2026-03-25 workbook update | B22: Raw vs derived split added; see Raw_Primitives_Catalog, Derived_Features_Catalog, Options_Chain_Raw_Spec, Volume_Baseline_Raw_Spec, and Playbook_Module_Audit.
A23: Legacy sheet note | B23: Raw_Catalog is retained for continuity but is now a mixed legacy catalog; use the new split sheets as source of truth.

Sheet Controls
A1: Controls & Selected Scenario Parameters
A3: Frequency | B3: Monthly | D3: Notes
A4: Start date | B4: 46023 | D4: Set scenario ID to 1=Baseline, 2=Stress, 3=Squeeze. | E4: Web baseline snapshot is March 2026; anchor rows are scaled around that point.
A5: End date | B5: 46357 | D5: Noise scale is a placeholder control for future generator logic. | E5: Fields without a clean public baseline feed remain synthetic placeholders.
A6: Selected scenario ID | B6: 1 | D6: Current workbook uses deterministic shifts to keep tests reproducible.
A7: Selected scenario name | B7: =INDEX(Scenario_Packs!$B$2:$B$4,$B$10)
A8: Noise scale | B8: 0.15
A10: Scenario row index | B10: =MATCH(B6,Scenario_Packs!$A$2:$A$4,0)
A13: Selected Scenario Parameters
A14: NVDA price multiplier | B14: =INDEX(Scenario_Packs!$C$2:$C$4,$B$10)
A15: NVDA volume multiplier | B15: =INDEX(Scenario_Packs!$D$2:$D$4,$B$10)
A16: Beta tape multiplier | B16: =INDEX(Scenario_Packs!$E$2:$E$4,$B$10)
A17: Asia handoff multiplier | B17: =INDEX(Scenario_Packs!$F$2:$F$4,$B$10)
A18: VIX add | B18: =INDEX(Scenario_Packs!$G$2:$G$4,$B$10)
A19: VVIX add | B19: =INDEX(Scenario_Packs!$H$2:$H$4,$B$10)
A20: VIX9D add | B20: =INDEX(Scenario_Packs!$I$2:$I$4,$B$10)
A21: SKEW add | B21: =INDEX(Scenario_Packs!$J$2:$J$4,$B$10)
A22: US10Y add (bp) | B22: =INDEX(Scenario_Packs!$K$2:$K$4,$B$10)
A23: US2Y add (bp) | B23: =INDEX(Scenario_Packs!$L$2:$L$4,$B$10)
A24: USDJPY multiplier | B24: =INDEX(Scenario_Packs!$M$2:$M$4,$B$10)
A25: Breadth add | B25: =INDEX(Scenario_Packs!$N$2:$N$4,$B$10)
A26: Dealer gamma shift | B26: =INDEX(Scenario_Packs!$O$2:$O$4,$B$10)
A27: Gamma concentration add | B27: =INDEX(Scenario_Packs!$P$2:$P$4,$B$10)
A28: ATM IV add | B28: =INDEX(Scenario_Packs!$Q$2:$Q$4,$B$10)
A29: Term slope add | B29: =INDEX(Scenario_Packs!$R$2:$R$4,$B$10)
A30: Skew slope add | B30: =INDEX(Scenario_Packs!$S$2:$S$4,$B$10)
A31: Call/put imbalance add | B31: =INDEX(Scenario_Packs!$T$2:$T$4,$B$10)
A32: OI concentration add | B32: =INDEX(Scenario_Packs!$U$2:$U$4,$B$10)
A33: RV20d add | B33: =INDEX(Scenario_Packs!$V$2:$V$4,$B$10)

Sheet Scenario_Packs
A1: Scenario Packs
A3: Scenario_ID | B3: Scenario_Name | C3: NVDA_Price_Mult | D3: NVDA_Vol_Mult | E3: Beta_Mult | F3: Asia_Mult | G3: VIX_Add | H3: VVIX_Add | I3: VIX9D_Add | J3: SKEW_Add | K3: US10Y_Add_bp | L3: US2Y_Add_bp | M3: USDJPY_Mult | N3: Breadth_Add | O3: Dealer_Gamma_Shift | P3: Gamma_Conc_Add | Q3: ATM_IV_Add | R3: Term_Slope_Add | S3: Skew_Slope_Add | T3: CallPut_Imbal_Add | U3: OI_Conc_Add | V3: RV20d_Add
A4: 1 | B4: Baseline | C4: 1 | D4: 1 | E4: 1 | F4: 1 | G4: 0 | H4: 0 | I4: 0 | J4: 0 | K4: 0 | L4: 0 | M4: 1 | N4: 0 | O4: 0 | P4: 0 | Q4: 0 | R4: 0 | S4: 0 | T4: 0 | U4: 0 | V4: 0
A5: 2 | B5: Stress | C5: 0.93 | D5: 1.25 | E5: 0.97 | F5: 0.95 | G5: 6 | H5: 14 | I5: 8 | J5: 6 | K5: 35 | L5: 20 | M5: 0.97 | N5: -0.12 | O5: -0.4 | P5: 0.1 | Q5: 0.08 | R5: 0.05 | S5: 0.04 | T5: -0.1 | U5: 0.06 | V5: 0.08
A6: 3 | B6: Squeeze | C6: 1.08 | D6: 1.2 | E6: 1.03 | F6: 1.01 | G6: -1 | H6: 3 | I6: 2 | J6: -2 | K6: 8 | L6: 4 | M6: 1.01 | N6: 0.08 | O6: 0.45 | P6: 0.18 | Q6: 0.04 | R6: -0.02 | S6: -0.03 | T6: 0.18 | U6: 0.1 | V6: 0.04

Sheet Raw_Catalog
A1: Raw Input Catalog
A2: Legacy mixed catalog retained for continuity only; use Raw_Primitives_Catalog and Derived_Features_Catalog as the source of truth.
A3: Family | B3: Field_ID | C3: Field_Name | D3: Unit | E3: Purpose | F3: Typical Source Class | G3: Why It Matters | H3: Notes
A4: US beta futures | B4: R01 | C4: ES futures | D4: index level | E4: Broad US beta tape | F4: futures / vendor feed | G4: Continuous overnight discovery for US risk | H4: Preferred over cash ETF as primary beta tape
A5: US beta futures | B5: R02 | C5: NQ futures | D5: index level | E5: US tech beta tape | F5: futures / vendor feed | G5: Best live proxy for US tech / growth beta | H5: Critical for NVDA beta-residual work
A6: Single-name execution | B6: R03 | C6: NVDA close / spot | D6: price | E6: Underlying price state | F6: single-name market data | G6: Primary single-name state | H6: Use with volume to derive VWAP
A7: Single-name execution | B7: R04 | C7: NVDA high | D7: price | E7: Range state | F7: single-name market data | G7: Captures realised intraperiod excursion | H7: Used for range / trap proxies
A8: Single-name execution | B8: R05 | C8: NVDA low | D8: price | E8: Range state | F8: single-name market data | G8: Captures realised intraperiod excursion | H8: Used for range / trap proxies
A9: Single-name execution | B9: R06 | C9: NVDA volume | D9: shares or $ | E9: Participation / execution state | F9: single-name market data | G9: Needed for VWAP, RVOL, participation baselines | H9: VWAP is derived, not raw
A10: Sector / industry | B10: R07 | C10: XLK / tech proxy | D10: index / ETF level | E10: US tech sector state | F10: sector market data | G10: Helps separate broad beta from tech leadership | H10: Proxy until cleaner IT sector feed
A11: Sector / industry | B11: R08 | C11: SOX / semis complex | D11: index level | E11: Semiconductor leadership | F11: sector market data | G11: NVDA often trades as semis leader | H11: Prefer SOX first-class state
A12: Asia handoff | B12: R09 | C12: Nikkei 225 | D12: index level | E12: Japan overnight risk handoff | F12: Asia market data | G12: Captures overnight risk and carry unwind tone | H12: Could use futures later
A13: Asia handoff | B13: R10 | C13: Hang Seng Index | D13: index level | E13: Hong Kong overnight risk handoff | F13: Asia market data | G13: Captures China / HK equity sentiment | H13: Use with HSTECH
A14: Asia handoff | B14: R11 | C14: Hang Seng TECH | D14: index level | E14: China-tech / HK tech sentiment | F14: Asia market data | G14: Adds tech-specific Asia context | H14: Useful for overnight tech repricing
... A55: Temporal Step1 | B55: R52 | C55: Close imbalance proxy | D55: signed ratio | E55: Late-session auction / imbalance pressure proxy | F55: auction / imbalance feed | G55: Optional close-window refinement | H55: Optional v2 field

Sheet Anchor_Data
A1: Anchor Data (Web-Seeded + Synthetic Expansion)
A2: March 2026 live web baseline blended into the anchor surface. Unresolved options-chain / breadth internals remain synthetic placeholders for now.
A4: Date | B4: NVDA_Close | C4: NVDA_High | D4: NVDA_Low | E4: NVDA_Volume_M | F4: ES | G4: NQ | H4: XLK | I4: SOX | J4: NKY | K4: HSI | L4: HSTECH | M4: VIX | N4: VVIX | O4: VIX9D | P4: SKEW | Q4: US10Y_bp | R4: US2Y_bp | S4: USDJPY | T4: SPX_Breadth | U4: NDX_Breadth | V4: SOX_Breadth | W4: Dealer_Gamma | X4: Gamma_Conc | Y4: ATM_IV | Z4: Term_Slope | AA4: Skew_Slope | AB4: CallPut_Imbal | AC4: OI_Conc | AD4: RV20d | AE4: Event_Flag
A5: 46023 | B5: 188.72609 | C5: 198.38304 | D5: 174.36188 | E5: 900 | F5: 6513.2647 | G5: 23869.734 | H5: 141.78029 | I5: 8001.5736 | J5: 54863.656 | K5: 25733.69 | L5: 4854.8218 | M5: 21.313011 | N5: 121.53462 | O5: 18.966458 | P5: 147.14694 | Q5: 431.08592 | R5: 382.78055 | S5: 160.4178 | T5: 0.53 | U5: 0.55 | V5: 0.57 | W5: 0.15 | X5: 0.42 | Y5: 0.42 | Z5: 0.03 | AA5: 0.11 | AB5: 0.08 | AC5: 0.47 | AD5: 0.38 | AE5: 0
A6: 46054 | B6: 195.4663 | C6: 205.46815 | D6: 180.58909 | E6: 935 | F6: 6594.6805 | G6: 24367.02 | H6: 143.13058 | I6: 8140.7314 | J6: 55520.706 | K6: 25993.318 | L6: 4935.2481 | M6: 21.852581 | N6: 124.23538 | O6: 19.602917 | P6: 148.20556 | Q6: 434.12888 | R6: 385.61596 | S6: 161.2956 | T6: 0.56 | U6: 0.58 | V6: 0.59 | W6: 0.1 | X6: 0.44 | Y6: 0.4 | Z6: 0.02 | AA6: 0.1 | AB6: 0.06 | AC6: 0.48 | AD6: 0.36 | AE6: 0
A7: 46082 | B7: 186.03 | C7: 195.549 | D7: 171.871 | E7: 970 | F7: 6506.48 | G7: 23898.15 | H7: 140.43 | I7: 7914.6 | J7: 54453 | K7: 25321.34 | L7: 4796.33 | M7: 25.09 | N7: 140.44 | O7: 24.44 | P7: 152.44 | Q7: 425 | R7: 379 | S7: 159.54 | T7: 0.44 | U7: 0.42 | V7: 0.4 | W7: -0.35 | X7: 0.39 | Y7: 0.46 | Z7: 0.06 | AA7: 0.15 | AB7: -0.14 | AC7: 0.45 | AD7: 0.43 | AE7: 1
A8: 46113 | B8: 199.51044 | C8: 209.71922 | D8: 184.32542 | E8: 1005 | F8: 6662.527 | G8: 24921.139 | H8: 145.83115 | I8: 8332.0734 | J8: 56670.543 | K8: 26176.584 | L8: 4986.4284 | M8: 23.066613 | N8: 130.98731 | O8: 21.385 | P8: 150.32278 | Q8: 439.20048 | R8: 389.39651 | S8: 162.50257 | T8: 0.58 | U8: 0.6 | V8: 0.62 | W8: -0.05 | X8: 0.46 | Y8: 0.43 | Z8: 0.04 | AA8: 0.13 | AB8: 0.02 | AC8: 0.5 | AD8: 0.4 | AE8: 0
A9: 46143 | B9: 207.5987 | C9: 218.22135 | D9: 191.79807 | E9: 1040 | F9: 6791.4353 | G9: 25588.923 | H9: 148.53173 | I9: 8506.0207 | J9: 57656.118 | K9: 26588.934 | L9: 5074.1662 | M9: 22.122366 | N9: 128.28654 | O9: 20.239375 | P9: 149.26417 | Q9: 445.2864 | R9: 394.12219 | S9: 163.81927 | T9: 0.6 | U9: 0.63 | V9: 0.65 | W9: 0.05 | X9: 0.49 | Y9: 0.41 | Z9: 0.03 | AA9: 0.12 | AB9: 0.05 | AC9: 0.52 | AD9: 0.39 | AE9: 0
A10: 46174 | B10: 215.68696 | C10: 226.72348 | D10: 199.27072 | E10: 1075 | F10: 6886.4204 | G10: 26086.209 | H10: 151.23231 | I10: 8662.5732 | J10: 58559.561 | K10: 26909.651 | L10: 5147.281 | M10: 21.178118 | N10: 122.885 | O10: 19.221042 | P10: 147.14694 | Q10: 448.32936 | R10: 396.01247 | S10: 164.58734 | T10: 0.61 | U10: 0.64 | V10: 0.66 | W10: 0.1 | X10: 0.51 | Y10: 0.39 | Z10: 0.02 | AA10: 0.11 | AB10: 0.08 | AC10: 0.53 | AD10: 0.37 | AE10: 0
A11: 46204 | B11: 223.77522 | C11: 235.22561 | D11: 206.74338 | E11: 1110 | F11: 6988.1902 | G11: 26682.952 | H11: 153.93288 | I11: 8906.0993 | J11: 59463.005 | K11: 27337.273 | L11: 5264.2646 | M11: 20.503656 | N11: 120.18423 | O11: 18.457292 | P11: 146.08833 | Q11: 451.37232 | R11: 397.90274 | S11: 165.90404 | T11: 0.63 | U11: 0.67 | V11: 0.69 | W11: 0.18 | X11: 0.54 | Y11: 0.38 | Z11: 0.01 | AA11: 0.1 | AB11: 0.12 | AC11: 0.55 | AD11: 0.35 | AE11: 0
A12: 46235 | B12: 230.51543 | C12: 242.31072 | D12: 212.97059 | E12: 1145 | F12: 7049.2521 | G12: 27052.365 | H12: 155.95832 | I12: 9062.6519 | J12: 60120.054 | K12: 27673.262 | L12: 5344.6909 | M12: 20.098978 | N12: 118.83385 | O12: 18.075417 | P12: 145.02972 | Q12: 453.40096 | R12: 399.79302 | S12: 166.56239 | T12: 0.64 | U12: 0.68 | V12: 0.7 | W12: 0.2 | X12: 0.56 | Y12: 0.37 | Z12: 0.01 | AA12: 0.1 | AB12: 0.14 | AC12: 0.57 | AD12: 0.34 | AE12: 0
A13: 46266 | B13: 226.4713 | C13: 238.05965 | D13: 209.23426 | E13: 1180 | F13: 6974.6209 | G13: 26597.703 | H13: 154.60803 | I13: 8975.6782 | J13: 59052.348 | K13: 27108.19 | L13: 5235.0187 | M13: 22.661935 | N13: 129.63692 | O13: 22.785208 | P13: 149.26417 | Q13: 446.30072 | R13: 395.06733 | S13: 165.02624 | T13: 0.51 | U13: 0.52 | V13: 0.54 | W13: -0.1 | X13: 0.48 | Y13: 0.41 | Z13: 0.04 | AA13: 0.12 | AB13: 0 | AC13: 0.51 | AD13: 0.38 | AE13: 1
A14: 46296 | B14: 237.25565 | C14: 249.39583 | D14: 219.1978 | E14: 1215 | F14: 7110.3139 | G14: 27308.112 | H14: 157.98375 | I14: 9184.4149 | J14: 60777.104 | K14: 28039.795 | L14: 5425.1172 | M14: 21.447903 | N14: 124.23538 | O14: 19.8575 | P14: 147.14694 | Q14: 457.45823 | R14: 402.62843 | S14: 166.89157 | T14: 0.62 | U14: 0.66 | V14: 0.68 | W14: 0.12 | X14: 0.58 | Y14: 0.39 | Z14: 0.02 | AA14: 0.11 | AB14: 0.1 | AC14: 0.58 | AD14: 0.36 | AE14: 0
A15: 46327 | B15: 248.04 | C15: 260.732 | D15: 229.16133 | E15: 1250 | F15: 7205.299 | G15: 27904.855 | H15: 160.68433 | I15: 9393.1516 | J15: 61844.81 | K15: 28467.417 | L15: 5527.4779 | M15: 20.368763 | N15: 121.53462 | O15: 18.839167 | P15: 146.08833 | Q15: 461.51551 | R15: 405.46384 | S15: 167.87909 | T15: 0.64 | U15: 0.68 | V15: 0.7 | W15: 0.18 | X15: 0.6 | Y15: 0.38 | Z15: 0.01 | AA15: 0.1 | AB15: 0.12 | AC15: 0.6 | AD15: 0.35 | AE15: 0
A16: 46357 | B16: 256.12826 | C16: 269.23413 | D16: 236.63399 | E16: 1285 | F16: 7300.2841 | G16: 28387.933 | H16: 163.3849 | I16: 9601.8884 | J16: 62748.253 | K16: 28895.039 | L16: 5615.2156 | M16: 19.694301 | N16: 117.48346 | O16: 17.820833 | P16: 145.02972 | Q16: 464.55847 | R16: 408.29925 | S16: 169.19579 | T16: 0.66 | U16: 0.7 | V16: 0.72 | W16: 0.22 | X16: 0.63 | Y16: 0.36 | Z16: 0.01 | AA16: 0.09 | AB16: 0.16 | AC16: 0.62 | AD16: 0.33 | AE16: 0

Sheet Live_Web_Baseline
A1: Live Web Baseline Snapshot
A2: Mixture of official and reputable public web sources used only to pull the workbook back into the right postcode.
A3: Fields without a clean public baseline feed remain synthetic elsewhere in the workbook.
A5: Metric | B5: Value | C5: Observed date | D5: Source | E5: Notes
A6: NVDA latest close | B6: 186.03 | C6: 2026-03-11 | D6: https://www.macrotrends.net/stocks/charts/NVDA/nvidia/stock-price-history/1000 | E6: Macrotrends adjusted history page
A7: NVDA 2026 YTD high | B7: 195.549 | C7: 2026-03-11 | D7: https://www.macrotrends.net/stocks/charts/NVDA/nvidia/stock-price-history/1000 | E7: Used as ballpark high anchor
A8: NVDA 2026 YTD low | B8: 171.871 | C8: 2026-03-11 | D8: https://www.macrotrends.net/stocks/charts/NVDA/nvidia/stock-price-history/1000 | E8: Used as ballpark low anchor
A9: VIX prev close | B9: 25.09 | C9: 2026-03-18 | D9: https://www.cboe.com/tradable-products/vix | E9: Official Cboe VIX page
A10: VIX 52w high | B10: 60.13 | C10: 2026-03-18 | D10: https://www.cboe.com/tradable-products/vix | E10: Official Cboe VIX page
A11: VIX 52w low | B11: 13.38 | C11: 2026-03-18 | D11: https://www.cboe.com/tradable-products/vix | E11: Official Cboe VIX page
A12: US 10Y yield (%) | B12: 4.25 | C12: 2026-03-19 | D12: https://fred.stlouisfed.org/series/DGS10 | E12: FRED / Fed H.15
A13: US 2Y yield (%) | B13: 3.79 | C13: 2026-03-19 | D13: https://fred.stlouisfed.org/series/DGS2 | E13: FRED / Fed H.15
A14: USDJPY | B14: 159.54 | C14: 2026-03-13 | D14: https://fred.stlouisfed.org/series/DEXJPUS | E14: FRED FX daily rate
A15: S&P 500 close | B15: 6506.48 | C15: 2026-03-20 | D15: https://fred.stlouisfed.org/series/SP500 | E15: Used as ES proxy in workbook
A16: NASDAQ-100 close | B16: 23898.15 | C16: 2026-03-20 | D16: https://fred.stlouisfed.org/series/NASDAQ100 | E16: Used as NQ proxy in workbook
A17: XLK close | B17: 140.43 | C17: 2026-03-11 | D17: https://stockanalysis.com/etf/xlk/history/ | E17: Public ETF history page
... A24: SKEW close | B24: 152.44 | C24: 2026-03-11 | D24: https://ycharts.com/indicators/skew_index | E24: Public historical close
A26: Recent daily observations used as live baseline snippets
A27: Series | B27: Date | C27: Value | D27: Source | E27: Notes
A28: DGS10 | B28: 2026-03-19 | C28: 4.25 | D28: https://fred.stlouisfed.org/series/DGS10
A29: DGS10 | B29: 2026-03-18 | C29: 4.26 | D29: https://fred.stlouisfed.org/series/DGS10
A30: DGS10 | B30: 2026-03-17 | C30: 4.2 | D30: https://fred.stlouisfed.org/series/DGS10
A31: DGS10 | B31: 2026-03-16 | C31: 4.23 | D31: https://fred.stlouisfed.org/series/DGS10
A32: DGS10 | B32: 2026-03-13 | C32: 4.28 | D32: https://fred.stlouisfed.org/series/DGS10
A33: DGS2 | B33: 2026-03-19 | C33: 3.79 | D33: https://fred.stlouisfed.org/series/DGS2
A34: DGS2 | B34: 2026-03-18 | C34: 3.76 | D34: https://fred.stlouisfed.org/series/DGS2
A35: DGS2 | B35: 2026-03-17 | C35: 3.68 | D35: https://fred.stlouisfed.org/series/DGS2
A36: DGS2 | B36: 2026-03-16 | C36: 3.68 | D36: https://fred.stlouisfed.org/series/DGS2
A37: DGS2 | B37: 2026-03-13 | C37: 3.73 | D37: https://fred.stlouisfed.org/series/DGS2
A38: DEXJPUS | B38: 2026-03-13 | C38: 159.54 | D38: https://fred.stlouisfed.org/series/DEXJPUS
A39: DEXJPUS | B39: 2026-03-12 | C39: 159.21 | D39: https://fred.stlouisfed.org/series/DEXJPUS
... A52: NASDAQ100 | B52: 2026-03-16 | C52: 24655.34 | D52: https://fred.stlouisfed.org/series/NASDAQ100

Sheet Synthetic_Raw
A1: Synthetic Raw Paths (Scenario-Adjusted)
A2: Formula-driven from Anchor_Data plus scenario controls.
A4: Date | B4: NVDA_Close | C4: NVDA_High | D4: NVDA_Low | E4: NVDA_Volume_M | F4: ES | G4: NQ | H4: XLK | I4: SOX | J4: NKY | K4: HSI | L4: HSTECH | M4: VIX | N4: VVIX | O4: VIX9D | P4: SKEW | Q4: US10Y_bp | R4: US2Y_bp | S4: USDJPY | T4: SPX_Breadth | U4: NDX_Breadth | V4: SOX_Breadth | W4: Dealer_Gamma | X4: Gamma_Conc | Y4: ATM_IV | Z4: Term_Slope | AA4: Skew_Slope | AB4: CallPut_Imbal | AC4: OI_Conc | AD4: RV20d | AE4: Event_Flag
A5: =Anchor_Data!A5 | B5: =Anchor_Data!B5*Controls!$B$14 | C5: =Anchor_Data!C5*Controls!$B$14 | D5: =Anchor_Data!D5*Controls!$B$14 | E5: =Anchor_Data!E5*Controls!$B$15 | F5: =Anchor_Data!F5*Controls!$B$16 | G5: =Anchor_Data!G5*Controls!$B$16 | H5: =Anchor_Data!H5*Controls!$B$16 | I5: =Anchor_Data!I5*Controls!$B$16 | J5: =Anchor_Data!J5*Controls!$B$17 | K5: =Anchor_Data!K5*Controls!$B$17 | L5: =Anchor_Data!L5*Controls!$B$17 | M5: =Anchor_Data!M5+Controls!$B$18 | N5: =Anchor_Data!N5+Controls!$B$19 | O5: =Anchor_Data!O5+Controls!$B$20 | P5: =Anchor_Data!P5+Controls!$B$21 | Q5: =Anchor_Data!Q5+Controls!$B$22 | R5: =Anchor_Data!R5+Controls!$B$23 | S5: =Anchor_Data!S5*Controls!$B$24 | T5: =MAX(0,MIN(1,Anchor_Data!T5+Controls!$B$25)) | U5: =MAX(0,MIN(1,Anchor_Data!U5+Controls!$B$25)) | V5: =MAX(0,MIN(1,Anchor_Data!V5+Controls!$B$25)) | W5: =MAX(-1,MIN(1,Anchor_Data!W5+Controls!$B$26)) | X5: =MAX(0,MIN(1,Anchor_Data!X5+Controls!$B$27)) | Y5: =MAX(0,Anchor_Data!Y5+Controls!$B$28) | Z5: =MAX(0,Anchor_Data!Z5+Controls!$B$29) | AA5: =MAX(0,Anchor_Data!AA5+Controls!$B$30) | AB5: =MAX(0,MIN(1,Anchor_Data!AB5+Controls!$B$31)) | AC5: =Anchor_Data!AC5+Controls!$B$32
A6: =Anchor_Data!A6 | B6: =Anchor_Data!B6*Controls!$B$14 | C6: =Anchor_Data!C6*Controls!$B$14 | D6: =Anchor_Data!D6*Controls!$B$14 | E6: =Anchor_Data!E6*Controls!$B$15 | F6: =Anchor_Data!F6*Controls!$B$16 | G6: =Anchor_Data!G6*Controls!$B$16 | H6: =Anchor_Data!H6*Controls!$B$16 | I6: =Anchor_Data!I6*Controls!$B$16 | J6: =Anchor_Data!J6*Controls!$B$17 | K6: =Anchor_Data!K6*Controls!$B$17 | L6: =Anchor_Data!L6*Controls!$B$17 | M6: =Anchor_Data!M6+Controls!$B$18 | N6: =Anchor_Data!N6+Controls!$B$19 | O6: =Anchor_Data!O6+Controls!$B$20 | P6: =Anchor_Data!P6+Controls!$B$21 | Q6: =Anchor_Data!Q6+Controls!$B$22 | R6: =Anchor_Data!R6+Controls!$B$23 | S6: =Anchor_Data!S6*Controls!$B$24 | T6: =MAX(0,MIN(1,Anchor_Data!T6+Controls!$B$25)) | U6: =MAX(0,MIN(1,Anchor_Data!U6+Controls!$B$25)) | V6: =MAX(0,MIN(1,Anchor_Data!V6+Controls!$B$25)) | W6: =MAX(-1,MIN(1,Anchor_Data!W6+Controls!$B$26)) | X6: =MAX(0,MIN(1,Anchor_Data!X6+Controls!$B$27)) | Y6: =MAX(0,Anchor_Data!Y6+Controls!$B$28) | Z6: =MAX(0,Anchor_Data!Z6+Controls!$B$29) | AA6: =MAX(0,Anchor_Data!AA6+Controls!$B$30) | AB6: =MAX(0,MIN(1,Anchor_Data!AB6+Controls!$B$31)) | AC6: =Anchor_Data!AC6+Controls!$B$32
A7: =Anchor_Data!A7 | B7: =Anchor_Data!B7*Controls!$B$14 | C7: =Anchor_Data!C7*Controls!$B$14 | D7: =Anchor_Data!D7*Controls!$B$14 | E7: =Anchor_Data!E7*Controls!$B$15 | F7: =Anchor_Data!F7*Controls!$B$16 | G7: =Anchor_Data!G7*Controls!$B$16 | H7: =Anchor_Data!H7*Controls!$B$16 | I7: =Anchor_Data!I7*Controls!$B$16 | J7: =Anchor_Data!J7*Controls!$B$17 | K7: =Anchor_Data!K7*Controls!$B$17 | L7: =Anchor_Data!L7*Controls!$B$17 | M7: =Anchor_Data!M7+Controls!$B$18 | N7: =Anchor_Data!N7+Controls!$B$19 | O7: =Anchor_Data!O7+Controls!$B$20 | P7: =Anchor_Data!P7+Controls!$B$21 | Q7: =Anchor_Data!Q7+Controls!$B$22 | R7: =Anchor_Data!R7+Controls!$B$23 | S7: =Anchor_Data!S7*Controls!$B$24 | T7: =MAX(0,MIN(1,Anchor_Data!T7+Controls!$B$25)) | U7: =MAX(0,MIN(1,Anchor_Data!U7+Controls!$B$25)) | V7: =MAX(0,MIN(1,Anchor_Data!V7+Controls!$B$25)) | W7: =MAX(-1,MIN(1,Anchor_Data!W7+Controls!$B$26)) | X7: =MAX(0,MIN(1,Anchor_Data!X7+Controls!$B$27)) | Y7: =MAX(0,Anchor_Data!Y7+Controls!$B$28) | Z7: =MAX(0,Anchor_Data!Z7+Controls!$B$29) | AA7: =MAX(0,Anchor_Data!AA7+Controls!$B$30) | AB7: =MAX(0,MIN(1,Anchor_Data!AB7+Controls!$B$31)) | AC7: =Anchor_Data!AC7+Controls!$B$32
A8: =Anchor_Data!A8 | B8: =Anchor_Data!B8*Controls!$B$14 | C8: =Anchor_Data!C8*Controls!$B$14 | D8: =Anchor_Data!D8*Controls!$B$14 | E8: =Anchor_Data!E8*Controls!$B$15 | F8: =Anchor_Data!F8*Controls!$B$16 | G8: =Anchor_Data!G8*Controls!$B$16 | H8: =Anchor_Data!H8*Controls!$B$16 | I8: =Anchor_Data!I8*Controls!$B$16 | J8: =Anchor_Data!J8*Controls!$B$17 | K8: =Anchor_Data!K8*Controls!$B$17 | L8: =Anchor_Data!L8*Controls!$B$17 | M8: =Anchor_Data!M8+Controls!$B$18 | N8: =Anchor_Data!N8+Controls!$B$19 | O8: =Anchor_Data!O8+Controls!$B$20 | P8: =Anchor_Data!P8+Controls!$B$21 | Q8: =Anchor_Data!Q8+Controls!$B$22 | R8: =Anchor_Data!R8+Controls!$B$23 | S8: =Anchor_Data!S8*Controls!$B$24 | T8: =MAX(0,MIN(1,Anchor_Data!T8+Controls!$B$25)) | U8: =MAX(0,MIN(1,Anchor_Data!U8+Controls!$B$25)) | V8: =MAX(0,MIN(1,Anchor_Data!V8+Controls!$B$25)) | W8: =MAX(-1,MIN(1,Anchor_Data!W8+Controls!$B$26)) | X8: =MAX(0,MIN(1,Anchor_Data!X8+Controls!$B$27)) | Y8: =MAX(0,Anchor_Data!Y8+Controls!$B$28) | Z8: =MAX(0,Anchor_Data!Z8+Controls!$B$29) | AA8: =MAX(0,Anchor_Data!AA8+Controls!$B$30) | AB8: =MAX(0,MIN(1,Anchor_Data!AB8+Controls!$B$31)) | AC8: =Anchor_Data!AC8+Controls!$B$32
A9: =Anchor_Data!A9 | B9: =Anchor_Data!B9*Controls!$B$14 | C9: =Anchor_Data!C9*Controls!$B$14 | D9: =Anchor_Data!D9*Controls!$B$14 | E9: =Anchor_Data!E9*Controls!$B$15 | F9: =Anchor_Data!F9*Controls!$B$16 | G9: =Anchor_Data!G9*Controls!$B$16 | H9: =Anchor_Data!H9*Controls!$B$16 | I9: =Anchor_Data!I9*Controls!$B$16 | J9: =Anchor_Data!J9*Controls!$B$17 | K9: =Anchor_Data!K9*Controls!$B$17 | L9: =Anchor_Data!L9*Controls!$B$17 | M9: =Anchor_Data!M9+Controls!$B$18 | N9: =Anchor_Data!N9+Controls!$B$19 | O9: =Anchor_Data!O9+Controls!$B$20 | P9: =Anchor_Data!P9+Controls!$B$21 | Q9: =Anchor_Data!Q9+Controls!$B$22 | R9: =Anchor_Data!R9+Controls!$B$23 | S9: =Anchor_Data!S9*Controls!$B$24 | T9: =MAX(0,MIN(1,Anchor_Data!T9+Controls!$B$25)) | U9: =MAX(0,MIN(1,Anchor_Data!U9+Controls!$B$25)) | V9: =MAX(0,MIN(1,Anchor_Data!V9+Controls!$B$25)) | W9: =MAX(-1,MIN(1,Anchor_Data!W9+Controls!$B$26)) | X9: =MAX(0,MIN(1,Anchor_Data!X9+Controls!$B$27)) | Y9: =MAX(0,Anchor_Data!Y9+Controls!$B$28) | Z9: =MAX(0,Anchor_Data!Z9+Controls!$B$29) | AA9: =MAX(0,Anchor_Data!AA9+Controls!$B$30) | AB9: =MAX(0,MIN(1,Anchor_Data!AB9+Controls!$B$31)) | AC9: =Anchor_Data!AC9+Controls!$B$32
A10: =Anchor_Data!A10 | B10: =Anchor_Data!B10*Controls!$B$14 | C10: =Anchor_Data!C10*Controls!$B$14 | D10: =Anchor_Data!D10*Controls!$B$14 | E10: =Anchor_Data!E10*Controls!$B$15 | F10: =Anchor_Data!F10*Controls!$B$16 | G10: =Anchor_Data!G10*Controls!$B$16 | H10: =Anchor_Data!H10*Controls!$B$16 | I10: =Anchor_Data!I10*Controls!$B$16 | J10: =Anchor_Data!J10*Controls!$B$17 | K10: =Anchor_Data!K10*Controls!$B$17 | L10: =Anchor_Data!L10*Controls!$B$17 | M10: =Anchor_Data!M10+Controls!$B$18 | N10: =Anchor_Data!N10+Controls!$B$19 | O10: =Anchor_Data!O10+Controls!$B$20 | P10: =Anchor_Data!P10+Controls!$B$21 | Q10: =Anchor_Data!Q10+Controls!$B$22 | R10: =Anchor_Data!R10+Controls!$B$23 | S10: =Anchor_Data!S10*Controls!$B$24 | T10: =MAX(0,MIN(1,Anchor_Data!T10+Controls!$B$25)) | U10: =MAX(0,MIN(1,Anchor_Data!U10+Controls!$B$25)) | V10: =MAX(0,MIN(1,Anchor_Data!V10+Controls!$B$25)) | W10: =MAX(-1,MIN(1,Anchor_Data!W10+Controls!$B$26)) | X10: =MAX(0,MIN(1,Anchor_Data!X10+Controls!$B$27)) | Y10: =MAX(0,Anchor_Data!Y10+Controls!$B$28) | Z10: =MAX(0,Anchor_Data!Z10+Controls!$B$29) | AA10: =MAX(0,Anchor_Data!AA10+Controls!$B$30) | AB10: =MAX(0,MIN(1,Anchor_Data!AB10+Controls!$B$31)) | AC10: =Anchor_Data!AC10+Controls!$B$32
A11: =Anchor_Data!A11 | B11: =Anchor_Data!B11*Controls!$B$14 | C11: =Anchor_Data!C11*Controls!$B$14 | D11: =Anchor_Data!D11*Controls!$B$14 | E11: =Anchor_Data!E11*Controls!$B$15 | F11: =Anchor_Data!F11*Controls!$B$16 | G11: =Anchor_Data!G11*Controls!$B$16 | H11: =Anchor_Data!H11*Controls!$B$16 | I11: =Anchor_Data!I11*Controls!$B$16 | J11: =Anchor_Data!J11*Controls!$B$17 | K11: =Anchor_Data!K11*Controls!$B$17 | L11: =Anchor_Data!L11*Controls!$B$17 | M11: =Anchor_Data!M11+Controls!$B$18 | N11: =Anchor_Data!N11+Controls!$B$19 | O11: =Anchor_Data!O11+Controls!$B$20 | P11: =Anchor_Data!P11+Controls!$B$21 | Q11: =Anchor_Data!Q11+Controls!$B$22 | R11: =Anchor_Data!R11+Controls!$B$23 | S11: =Anchor_Data!S11*Controls!$B$24 | T11: =MAX(0,MIN(1,Anchor_Data!T11+Controls!$B$25)) | U11: =MAX(0,MIN(1,Anchor_Data!U11+Controls!$B$25)) | V11: =MAX(0,MIN(1,Anchor_Data!V11+Controls!$B$25)) | W11: =MAX(-1,MIN(1,Anchor_Data!W11+Controls!$B$26)) | X11: =MAX(0,MIN(1,Anchor_Data!X11+Controls!$B$27)) | Y11: =MAX(0,Anchor_Data!Y11+Controls!$B$28) | Z11: =MAX(0,Anchor_Data!Z11+Controls!$B$29) | AA11: =MAX(0,Anchor_Data!AA11+Controls!$B$30) | AB11: =MAX(0,MIN(1,Anchor_Data!AB11+Controls!$B$31)) | AC11: =Anchor_Data!AC11+Controls!$B$32
A12: =Anchor_Data!A12 | B12: =Anchor_Data!B12*Controls!$B$14 | C12: =Anchor_Data!C12*Controls!$B$14 | D12: =Anchor_Data!D12*Controls!$B$14 | E12: =Anchor_Data!E12*Controls!$B$15 | F12: =Anchor_Data!F12*Controls!$B$16 | G12: =Anchor_Data!G12*Controls!$B$16 | H12: =Anchor_Data!H12*Controls!$B$16 | I12: =Anchor_Data!I12*Controls!$B$16 | J12: =Anchor_Data!J12*Controls!$B$17 | K12: =Anchor_Data!K12*Controls!$B$17 | L12: =Anchor_Data!L12*Controls!$B$17 | M12: =Anchor_Data!M12+Controls!$B$18 | N12: =Anchor_Data!N12+Controls!$B$19 | O12: =Anchor_Data!O12+Controls!$B$20 | P12: =Anchor_Data!P12+Controls!$B$21 | Q12: =Anchor_Data!Q12+Controls!$B$22 | R12: =Anchor_Data!R12+Controls!$B$23 | S12: =Anchor_Data!S12*Controls!$B$24 | T12: =MAX(0,MIN(1,Anchor_Data!T12+Controls!$B$25)) | U12: =MAX(0,MIN(1,Anchor_Data!U12+Controls!$B$25)) | V12: =MAX(0,MIN(1,Anchor_Data!V12+Controls!$B$25)) | W12: =MAX(-1,MIN(1,Anchor_Data!W12+Controls!$B$26)) | X12: =MAX(0,MIN(1,Anchor_Data!X12+Controls!$B$27)) | Y12: =MAX(0,Anchor_Data!Y12+Controls!$B$28) | Z12: =MAX(0,Anchor_Data!Z12+Controls!$B$29) | AA12: =MAX(0,Anchor_Data!AA12+Controls!$B$30) | AB12: =MAX(0,MIN(1,Anchor_Data!AB12+Controls!$B$31)) | AC12: =Anchor_Data!AC12+Controls!$B$32
A13: =Anchor_Data!A13 | B13: =Anchor_Data!B13*Controls!$B$14 | C13: =Anchor_Data!C13*Controls!$B$14 | D13: =Anchor_Data!D13*Controls!$B$14 | E13: =Anchor_Data!E13*Controls!$B$15 | F13: =Anchor_Data!F13*Controls!$B$16 | G13: =Anchor_Data!G13*Controls!$B$16 | H13: =Anchor_Data!H13*Controls!$B$16 | I13: =Anchor_Data!I13*Controls!$B$16 | J13: =Anchor_Data!J13*Controls!$B$17 | K13: =Anchor_Data!K13*Controls!$B$17 | L13: =Anchor_Data!L13*Controls!$B$17 | M13: =Anchor_Data!M13+Controls!$B$18 | N13: =Anchor_Data!N13+Controls!$B$19 | O13: =Anchor_Data!O13+Controls!$B$20 | P13: =Anchor_Data!P13+Controls!$B$21 | Q13: =Anchor_Data!Q13+Controls!$B$22 | R13: =Anchor_Data!R13+Controls!$B$23 | S13: =Anchor_Data!S13*Controls!$B$24 | T13: =MAX(0,MIN(1,Anchor_Data!T13+Controls!$B$25)) | U13: =MAX(0,MIN(1,Anchor_Data!U13+Controls!$B$25)) | V13: =MAX(0,MIN(1,Anchor_Data!V13+Controls!$B$25)) | W13: =MAX(-1,MIN(1,Anchor_Data!W13+Controls!$B$26)) | X13: =MAX(0,MIN(1,Anchor_Data!X13+Controls!$B$27)) | Y13: =MAX(0,Anchor_Data!Y13+Controls!$B$28) | Z13: =MAX(0,Anchor_Data!Z13+Controls!$B$29) | AA13: =MAX(0,Anchor_Data!AA13+Controls!$B$30) | AB13: =MAX(0,MIN(1,Anchor_Data!AB13+Controls!$B$31)) | AC13: =Anchor_Data!AC13+Controls!$B$32
A14: =Anchor_Data!A14 | B14: =Anchor_Data!B14*Controls!$B$14 | C14: =Anchor_Data!C14*Controls!$B$14 | D14: =Anchor_Data!D14*Controls!$B$14 | E14: =Anchor_Data!E14*Controls!$B$15 | F14: =Anchor_Data!F14*Controls!$B$16 | G14: =Anchor_Data!G14*Controls!$B$16 | H14: =Anchor_Data!H14*Controls!$B$16 | I14: =Anchor_Data!I14*Controls!$B$16 | J14: =Anchor_Data!J14*Controls!$B$17 | K14: =Anchor_Data!K14*Controls!$B$17 | L14: =Anchor_Data!L14*Controls!$B$17 | M14: =Anchor_Data!M14+Controls!$B$18 | N14: =Anchor_Data!N14+Controls!$B$19 | O14: =Anchor_Data!O14+Controls!$B$20 | P14: =Anchor_Data!P14+Controls!$B$21 | Q14: =Anchor_Data!Q14+Controls!$B$22 | R14: =Anchor_Data!R14+Controls!$B$23 | S14: =Anchor_Data!S14*Controls!$B$24 | T14: =MAX(0,MIN(1,Anchor_Data!T14+Controls!$B$25)) | U14: =MAX(0,MIN(1,Anchor_Data!U14+Controls!$B$25)) | V14: =MAX(0,MIN(1,Anchor_Data!V14+Controls!$B$25)) | W14: =MAX(-1,MIN(1,Anchor_Data!W14+Controls!$B$26)) | X14: =MAX(0,MIN(1,Anchor_Data!X14+Controls!$B$27)) | Y14: =MAX(0,Anchor_Data!Y14+Controls!$B$28) | Z14: =MAX(0,Anchor_Data!Z14+Controls!$B$29) | AA14: =MAX(0,Anchor_Data!AA14+Controls!$B$30) | AB14: =MAX(0,MIN(1,Anchor_Data!AB14+Controls!$B$31)) | AC14: =Anchor_Data!AC14+Controls!$B$32
A15: =Anchor_Data!A15 | B15: =Anchor_Data!B15*Controls!$B$14 | C15: =Anchor_Data!C15*Controls!$B$14 | D15: =Anchor_Data!D15*Controls!$B$14 | E15: =Anchor_Data!E15*Controls!$B$15 | F15: =Anchor_Data!F15*Controls!$B$16 | G15: =Anchor_Data!G15*Controls!$B$16 | H15: =Anchor_Data!H15*Controls!$B$16 | I15: =Anchor_Data!I15*Controls!$B$16 | J15: =Anchor_Data!J15*Controls!$B$17 | K15: =Anchor_Data!K15*Controls!$B$17 | L15: =Anchor_Data!L15*Controls!$B$17 | M15: =Anchor_Data!M15+Controls!$B$18 | N15: =Anchor_Data!N15+Controls!$B$19 | O15: =Anchor_Data!O15+Controls!$B$20 | P15: =Anchor_Data!P15+Controls!$B$21 | Q15: =Anchor_Data!Q15+Controls!$B$22 | R15: =Anchor_Data!R15+Controls!$B$23 | S15: =Anchor_Data!S15*Controls!$B$24 | T15: =MAX(0,MIN(1,Anchor_Data!T15+Controls!$B$25)) | U15: =MAX(0,MIN(1,Anchor_Data!U15+Controls!$B$25)) | V15: =MAX(0,MIN(1,Anchor_Data!V15+Controls!$B$25)) | W15: =MAX(-1,MIN(1,Anchor_Data!W15+Controls!$B$26)) | X15: =MAX(0,MIN(1,Anchor_Data!X15+Controls!$B$27)) | Y15: =MAX(0,Anchor_Data!Y15+Controls!$B$28) | Z15: =MAX(0,Anchor_Data!Z15+Controls!$B$29) | AA15: =MAX(0,Anchor_Data!AA15+Controls!$B$30) | AB15: =MAX(0,MIN(1,Anchor_Data!AB15+Controls!$B$31)) | AC15: =Anchor_Data!AC15+Controls!$B$32
A16: =Anchor_Data!A16 | B16: =Anchor_Data!B16*Controls!$B$14 | C16: =Anchor_Data!C16*Controls!$B$14 | D16: =Anchor_Data!D16*Controls!$B$14 | E16: =Anchor_Data!E16*Controls!$B$15 | F16: =Anchor_Data!F16*Controls!$B$16 | G16: =Anchor_Data!G16*Controls!$B$16 | H16: =Anchor_Data!H16*Controls!$B$16 | I16: =Anchor_Data!I16*Controls!$B$16 | J16: =Anchor_Data!J16*Controls!$B$17 | K16: =Anchor_Data!K16*Controls!$B$17 | L16: =Anchor_Data!L16*Controls!$B$17 | M16: =Anchor_Data!M16+Controls!$B$18 | N16: =Anchor_Data!N16+Controls!$B$19 | O16: =Anchor_Data!O16+Controls!$B$20 | P16: =Anchor_Data!P16+Controls!$B$21 | Q16: =Anchor_Data!Q16+Controls!$B$22 | R16: =Anchor_Data!R16+Controls!$B$23 | S16: =Anchor_Data!S16*Controls!$B$24 | T16: =MAX(0,MIN(1,Anchor_Data!T16+Controls!$B$25)) | U16: =MAX(0,MIN(1,Anchor_Data!U16+Controls!$B$25)) | V16: =MAX(0,MIN(1,Anchor_Data!V16+Controls!$B$25)) | W16: =MAX(-1,MIN(1,Anchor_Data!W16+Controls!$B$26)) | X16: =MAX(0,MIN(1,Anchor_Data!X16+Controls!$B$27)) | Y16: =MAX(0,Anchor_Data!Y16+Controls!$B$28) | Z16: =MAX(0,Anchor_Data!Z16+Controls!$B$29) | AA16: =MAX(0,Anchor_Data!AA16+Controls!$B$30) | AB16: =MAX(0,MIN(1,Anchor_Data!AB16+Controls!$B$31)) | AC16: =Anchor_Data!AC16+Controls!$B$32

Sheet Derived_Beta_Leadership
A1: Derived State: Beta & Leadership
A3: Date | B3: NVDA_Return | C3: ES_Return | D3: NQ_Return | E3: NVDA_vs_ES_Residual | F3: NVDA_vs_NQ_Residual | G3: NQ_vs_ES_Leadership | H3: SOX_vs_NQ_Leadership | I3: Tech_vs_ES_Leadership | J3: Breadth_Confirmation | K3: Beta_State_Score | L3: Comment
A4: =Synthetic_Raw!A5
A5: =Synthetic_Raw!A6 | B5: =(Synthetic_Raw!B6/Synthetic_Raw!B5)-1 | C5: =(Synthetic_Raw!F6/Synthetic_Raw!F5)-1 | D5: =(Synthetic_Raw!G6/Synthetic_Raw!G5)-1 | E5: =B5-C5 | F5: =B5-D5 | G5: =D5-C5 | H5: =((Synthetic_Raw!I6/Synthetic_Raw!I5)-1)-D5 | I5: =((Synthetic_Raw!H6/Synthetic_Raw!H5)-1)-C5 | J5: =AVERAGE(Synthetic_Raw!T6:Synthetic_Raw!V6) | K5: =0.35*F5+0.25*G5+0.20*H5+0.20*(J5-0.5) | L5: =IF(K5>0.03,"Positive beta / leadership state",IF(K5<-0.03,"Weak beta / leadership state","Mixed beta state"))
A6: =Synthetic_Raw!A7 | B6: =(Synthetic_Raw!B7/Synthetic_Raw!B6)-1 | C6: =(Synthetic_Raw!F7/Synthetic_Raw!F6)-1 | D6: =(Synthetic_Raw!G7/Synthetic_Raw!G6)-1 | E6: =B6-C6 | F6: =B6-D6 | G6: =D6-C6 | H6: =((Synthetic_Raw!I7/Synthetic_Raw!I6)-1)-D6 | I6: =((Synthetic_Raw!H7/Synthetic_Raw!H6)-1)-C6 | J6: =AVERAGE(Synthetic_Raw!T7:Synthetic_Raw!V7) | K6: =0.35*F6+0.25*G6+0.20*H6+0.20*(J6-0.5) | L6: =IF(K6>0.03,"Positive beta / leadership state",IF(K6<-0.03,"Weak beta / leadership state","Mixed beta state"))
A7: =Synthetic_Raw!A8 | B7: =(Synthetic_Raw!B8/Synthetic_Raw!B7)-1 | C7: =(Synthetic_Raw!F8/Synthetic_Raw!F7)-1 | D7: =(Synthetic_Raw!G8/Synthetic_Raw!G7)-1 | E7: =B7-C7 | F7: =B7-D7 | G7: =D7-C7 | H7: =((Synthetic_Raw!I8/Synthetic_Raw!I7)-1)-D7 | I7: =((Synthetic_Raw!H8/Synthetic_Raw!H7)-1)-C7 | J7: =AVERAGE(Synthetic_Raw!T8:Synthetic_Raw!V8) | K7: =0.35*F7+0.25*G7+0.20*H7+0.20*(J7-0.5) | L7: =IF(K7>0.03,"Positive beta / leadership state",IF(K7<-0.03,"Weak beta / leadership state","Mixed beta state"))
A8: =Synthetic_Raw!A9 | B8: =(Synthetic_Raw!B9/Synthetic_Raw!B8)-1 | C8: =(Synthetic_Raw!F9/Synthetic_Raw!F8)-1 | D8: =(Synthetic_Raw!G9/Synthetic_Raw!G8)-1 | E8: =B8-C8 | F8: =B8-D8 | G8: =D8-C8 | H8: =((Synthetic_Raw!I9/Synthetic_Raw!I8)-1)-D8 | I8: =((Synthetic_Raw!H9/Synthetic_Raw!H8)-1)-C8 | J8: =AVERAGE(Synthetic_Raw!T9:Synthetic_Raw!V9) | K8: =0.35*F8+0.25*G8+0.20*H8+0.20*(J8-0.5) | L8: =IF(K8>0.03,"Positive beta / leadership state",IF(K8<-0.03,"Weak beta / leadership state","Mixed beta state"))
A9: =Synthetic_Raw!A10 | B9: =(Synthetic_Raw!B10/Synthetic_Raw!B9)-1 | C9: =(Synthetic_Raw!F10/Synthetic_Raw!F9)-1 | D9: =(Synthetic_Raw!G10/Synthetic_Raw!G9)-1 | E9: =B9-C9 | F9: =B9-D9 | G9: =D9-C9 | H9: =((Synthetic_Raw!I10/Synthetic_Raw!I9)-1)-D9 | I9: =((Synthetic_Raw!H10/Synthetic_Raw!H9)-1)-C9 | J9: =AVERAGE(Synthetic_Raw!T10:Synthetic_Raw!V10) | K9: =0.35*F9+0.25*G9+0.20*H9+0.20*(J9-0.5) | L9: =IF(K9>0.03,"Positive beta / leadership state",IF(K9<-0.03,"Weak beta / leadership state","Mixed beta state"))
A10: =Synthetic_Raw!A11 | B10: =(Synthetic_Raw!B11/Synthetic_Raw!B10)-1 | C10: =(Synthetic_Raw!F11/Synthetic_Raw!F10)-1 | D10: =(Synthetic_Raw!G11/Synthetic_Raw!G10)-1 | E10: =B10-C10 | F10: =B10-D10 | G10: =D10-C10 | H10: =((Synthetic_Raw!I11/Synthetic_Raw!I10)-1)-D10 | I10: =((Synthetic_Raw!H11/Synthetic_Raw!H10)-1)-C10 | J10: =AVERAGE(Synthetic_Raw!T11:Synthetic_Raw!V11) | K10: =0.35*F10+0.25*G10+0.20*H10+0.20*(J10-0.5) | L10: =IF(K10>0.03,"Positive beta / leadership state",IF(K10<-0.03,"Weak beta / leadership state","Mixed beta state"))
A11: =Synthetic_Raw!A12 | B11: =(Synthetic_Raw!B12/Synthetic_Raw!B11)-1 | C11: =(Synthetic_Raw!F12/Synthetic_Raw!F11)-1 | D11: =(Synthetic_Raw!G12/Synthetic_Raw!G11)-1 | E11: =B11-C11 | F11: =B11-D11 | G11: =D11-C11 | H11: =((Synthetic_Raw!I12/Synthetic_Raw!I11)-1)-D11 | I11: =((Synthetic_Raw!H12/Synthetic_Raw!H11)-1)-C11 | J11: =AVERAGE(Synthetic_Raw!T12:Synthetic_Raw!V12) | K11: =0.35*F11+0.25*G11+0.20*H11+0.20*(J11-0.5) | L11: =IF(K11>0.03,"Positive beta / leadership state",IF(K11<-0.03,"Weak beta / leadership state","Mixed beta state"))
A12: =Synthetic_Raw!A13 | B12: =(Synthetic_Raw!B13/Synthetic_Raw!B12)-1 | C12: =(Synthetic_Raw!F13/Synthetic_Raw!F12)-1 | D12: =(Synthetic_Raw!G13/Synthetic_Raw!G12)-1 | E12: =B12-C12 | F12: =B12-D12 | G12: =D12-C12 | H12: =((Synthetic_Raw!I13/Synthetic_Raw!I12)-1)-D12 | I12: =((Synthetic_Raw!H13/Synthetic_Raw!H12)-1)-C12 | J12: =AVERAGE(Synthetic_Raw!T13:Synthetic_Raw!V13) | K12: =0.35*F12+0.25*G12+0.20*H12+0.20*(J12-0.5) | L12: =IF(K12>0.03,"Positive beta / leadership state",IF(K12<-0.03,"Weak beta / leadership state","Mixed beta state"))
A13: =Synthetic_Raw!A14 | B13: =(Synthetic_Raw!B14/Synthetic_Raw!B13)-1 | C13: =(Synthetic_Raw!F14/Synthetic_Raw!F13)-1 | D13: =(Synthetic_Raw!G14/Synthetic_Raw!G13)-1 | E13: =B13-C13 | F13: =B13-D13 | G13: =D13-C13 | H13: =((Synthetic_Raw!I14/Synthetic_Raw!I13)-1)-D13 | I13: =((Synthetic_Raw!H14/Synthetic_Raw!H13)-1)-C13 | J13: =AVERAGE(Synthetic_Raw!T14:Synthetic_Raw!V14) | K13: =0.35*F13+0.25*G13+0.20*H13+0.20*(J13-0.5) | L13: =IF(K13>0.03,"Positive beta / leadership state",IF(K13<-0.03,"Weak beta / leadership state","Mixed beta state"))
A14: =Synthetic_Raw!A15 | B14: =(Synthetic_Raw!B15/Synthetic_Raw!B14)-1 | C14: =(Synthetic_Raw!F15/Synthetic_Raw!F14)-1 | D14: =(Synthetic_Raw!G15/Synthetic_Raw!G14)-1 | E14: =B14-C14 | F14: =B14-D14 | G14: =D14-C14 | H14: =((Synthetic_Raw!I15/Synthetic_Raw!I14)-1)-D14 | I14: =((Synthetic_Raw!H15/Synthetic_Raw!H14)-1)-C14 | J14: =AVERAGE(Synthetic_Raw!T15:Synthetic_Raw!V15) | K14: =0.35*F14+0.25*G14+0.20*H14+0.20*(J14-0.5) | L14: =IF(K14>0.03,"Positive beta / leadership state",IF(K14<-0.03,"Weak beta / leadership state","Mixed beta state"))
A15: =Synthetic_Raw!A16 | B15: =(Synthetic_Raw!B16/Synthetic_Raw!B15)-1 | C15: =(Synthetic_Raw!F16/Synthetic_Raw!F15)-1 | D15: =(Synthetic_Raw!G16/Synthetic_Raw!G15)-1 | E15: =B15-C15 | F15: =B15-D15 | G15: =D15-C15 | H15: =((Synthetic_Raw!I16/Synthetic_Raw!I15)-1)-D15 | I15: =((Synthetic_Raw!H16/Synthetic_Raw!H15)-1)-C15 | J15: =AVERAGE(Synthetic_Raw!T16:Synthetic_Raw!V16) | K15: =0.35*F15+0.25*G15+0.20*H15+0.20*(J15-0.5) | L15: =IF(K15>0.03,"Positive beta / leadership state",IF(K15<-0.03,"Weak beta / leadership state","Mixed beta state"))

Sheet Derived_Vol_Rates_FX
A1: Derived State: Vol / Rates / FX
A3: Date | B3: VIX9D_vs_VIX | C3: VVIX_vs_VIX | D3: Rate_Slope_10s2s_bp | E3: Rate_Shock | F3: USDJPY_Change | G3: Vol_Stress_Score | H3: Tail_Risk_Score | I3: Cross_Asset_Pressure | J3: Macro_Veto_Flag | K3: Comment
A4: =Synthetic_Raw!A5
A5: =Synthetic_Raw!A6 | B5: =Synthetic_Raw!O6-Synthetic_Raw!M6 | C5: =(Synthetic_Raw!N6/Synthetic_Raw!M6)-1 | D5: =Synthetic_Raw!Q6-Synthetic_Raw!R6 | E5: =Synthetic_Raw!Q6-Synthetic_Raw!Q5 | F5: =(Synthetic_Raw!S6/Synthetic_Raw!S5)-1 | G5: =0.4*(B5/10)+0.3*C5+0.3*(Synthetic_Raw!M6/20) | H5: =(Synthetic_Raw!P6-135)/20 | I5: =0.35*G5+0.35*(ABS(E5)/25)+0.30*ABS(F5) | J5: =IF(OR(G5>0.85,I5>0.75,Synthetic_Raw!AC6=1),"VETO","OK") | K5: =IF(J5="VETO","Macro / vol caution","Normal watch")
A6: =Synthetic_Raw!A7 | B6: =Synthetic_Raw!O7-Synthetic_Raw!M7 | C6: =(Synthetic_Raw!N7/Synthetic_Raw!M7)-1 | D6: =Synthetic_Raw!Q7-Synthetic_Raw!R7 | E6: =Synthetic_Raw!Q7-Synthetic_Raw!Q6 | F6: =(Synthetic_Raw!S7/Synthetic_Raw!S6)-1 | G6: =0.4*(B6/10)+0.3*C6+0.3*(Synthetic_Raw!M7/20) | H6: =(Synthetic_Raw!P7-135)/20 | I6: =0.35*G6+0.35*(ABS(E6)/25)+0.30*ABS(F6) | J6: =IF(OR(G6>0.85,I6>0.75,Synthetic_Raw!AC7=1),"VETO","OK") | K6: =IF(J6="VETO","Macro / vol caution","Normal watch")
A7: =Synthetic_Raw!A8 | B7: =Synthetic_Raw!O8-Synthetic_Raw!M8 | C7: =(Synthetic_Raw!N8/Synthetic_Raw!M8)-1 | D7: =Synthetic_Raw!Q8-Synthetic_Raw!R8 | E7: =Synthetic_Raw!Q8-Synthetic_Raw!Q7 | F7: =(Synthetic_Raw!S8/Synthetic_Raw!S7)-1 | G7: =0.4*(B7/10)+0.3*C7+0.3*(Synthetic_Raw!M8/20) | H7: =(Synthetic_Raw!P8-135)/20 | I7: =0.35*G7+0.35*(ABS(E7)/25)+0.30*ABS(F7) | J7: =IF(OR(G7>0.85,I7>0.75,Synthetic_Raw!AC8=1),"VETO","OK") | K7: =IF(J7="VETO","Macro / vol caution","Normal watch")
A8: =Synthetic_Raw!A9 | B8: =Synthetic_Raw!O9-Synthetic_Raw!M9 | C8: =(Synthetic_Raw!N9/Synthetic_Raw!M9)-1 | D8: =Synthetic_Raw!Q9-Synthetic_Raw!R9 | E8: =Synthetic_Raw!Q9-Synthetic_Raw!Q8 | F8: =(Synthetic_Raw!S9/Synthetic_Raw!S8)-1 | G8: =0.4*(B8/10)+0.3*C8+0.3*(Synthetic_Raw!M9/20) | H8: =(Synthetic_Raw!P9-135)/20 | I8: =0.35*G8+0.35*(ABS(E8)/25)+0.30*ABS(F8) | J8: =IF(OR(G8>0.85,I8>0.75,Synthetic_Raw!AC9=1),"VETO","OK") | K8: =IF(J8="VETO","Macro / vol caution","Normal watch")
A9: =Synthetic_Raw!A10 | B9: =Synthetic_Raw!O10-Synthetic_Raw!M10 | C9: =(Synthetic_Raw!N10/Synthetic_Raw!M10)-1 | D9: =Synthetic_Raw!Q10-Synthetic_Raw!R10 | E9: =Synthetic_Raw!Q10-Synthetic_Raw!Q9 | F9: =(Synthetic_Raw!S10/Synthetic_Raw!S9)-1 | G9: =0.4*(B9/10)+0.3*C9+0.3*(Synthetic_Raw!M10/20) | H9: =(Synthetic_Raw!P10-135)/20 | I9: =0.35*G9+0.35*(ABS(E9)/25)+0.30*ABS(F9) | J9: =IF(OR(G9>0.85,I9>0.75,Synthetic_Raw!AC10=1),"VETO","OK") | K9: =IF(J9="VETO","Macro / vol caution","Normal watch")
A10: =Synthetic_Raw!A11 | B10: =Synthetic_Raw!O11-Synthetic_Raw!M11 | C10: =(Synthetic_Raw!N11/Synthetic_Raw!M11)-1 | D10: =Synthetic_Raw!Q11-Synthetic_Raw!R11 | E10: =Synthetic_Raw!Q11-Synthetic_Raw!Q10 | F10: =(Synthetic_Raw!S11/Synthetic_Raw!S10)-1 | G10: =0.4*(B10/10)+0.3*C10+0.3*(Synthetic_Raw!M11/20) | H10: =(Synthetic_Raw!P11-135)/20 | I10: =0.35*G10+0.35*(ABS(E10)/25)+0.30*ABS(F10) | J10: =IF(OR(G10>0.85,I10>0.75,Synthetic_Raw!AC11=1),"VETO","OK") | K10: =IF(J10="VETO","Macro / vol caution","Normal watch")
A11: =Synthetic_Raw!A12 | B11: =Synthetic_Raw!O12-Synthetic_Raw!M12 | C11: =(Synthetic_Raw!N12/Synthetic_Raw!M12)-1 | D11: =Synthetic_Raw!Q12-Synthetic_Raw!R12 | E11: =Synthetic_Raw!Q12-Synthetic_Raw!Q11 | F11: =(Synthetic_Raw!S12/Synthetic_Raw!S11)-1 | G11: =0.4*(B11/10)+0.3*C11+0.3*(Synthetic_Raw!M12/20) | H11: =(Synthetic_Raw!P12-135)/20 | I11: =0.35*G11+0.35*(ABS(E11)/25)+0.30*ABS(F11) | J11: =IF(OR(G11>0.85,I11>0.75,Synthetic_Raw!AC12=1),"VETO","OK") | K11: =IF(J11="VETO","Macro / vol caution","Normal watch")
A12: =Synthetic_Raw!A13 | B12: =Synthetic_Raw!O13-Synthetic_Raw!M13 | C12: =(Synthetic_Raw!N13/Synthetic_Raw!M13)-1 | D12: =Synthetic_Raw!Q13-Synthetic_Raw!R13 | E12: =Synthetic_Raw!Q13-Synthetic_Raw!Q12 | F12: =(Synthetic_Raw!S13/Synthetic_Raw!S12)-1 | G12: =0.4*(B12/10)+0.3*C12+0.3*(Synthetic_Raw!M13/20) | H12: =(Synthetic_Raw!P13-135)/20 | I12: =0.35*G12+0.35*(ABS(E12)/25)+0.30*ABS(F12) | J12: =IF(OR(G12>0.85,I12>0.75,Synthetic_Raw!AC13=1),"VETO","OK") | K12: =IF(J12="VETO","Macro / vol caution","Normal watch")
A13: =Synthetic_Raw!A14 | B13: =Synthetic_Raw!O14-Synthetic_Raw!M14 | C13: =(Synthetic_Raw!N14/Synthetic_Raw!M14)-1 | D13: =Synthetic_Raw!Q14-Synthetic_Raw!R14 | E13: =Synthetic_Raw!Q14-Synthetic_Raw!Q13 | F13: =(Synthetic_Raw!S14/Synthetic_Raw!S13)-1 | G13: =0.4*(B13/10)+0.3*C13+0.3*(Synthetic_Raw!M14/20) | H13: =(Synthetic_Raw!P14-135)/20 | I13: =0.35*G13+0.35*(ABS(E13)/25)+0.30*ABS(F13) | J13: =IF(OR(G13>0.85,I13>0.75,Synthetic_Raw!AC14=1),"VETO","OK") | K13: =IF(J13="VETO","Macro / vol caution","Normal watch")
A14: =Synthetic_Raw!A15 | B14: =Synthetic_Raw!O15-Synthetic_Raw!M15 | C14: =(Synthetic_Raw!N15/Synthetic_Raw!M15)-1 | D14: =Synthetic_Raw!Q15-Synthetic_Raw!R15 | E14: =Synthetic_Raw!Q15-Synthetic_Raw!Q14 | F14: =(Synthetic_Raw!S15/Synthetic_Raw!S14)-1 | G14: =0.4*(B14/10)+0.3*C14+0.3*(Synthetic_Raw!M15/20) | H14: =(Synthetic_Raw!P15-135)/20 | I14: =0.35*G14+0.35*(ABS(E14)/25)+0.30*ABS(F14) | J14: =IF(OR(G14>0.85,I14>0.75,Synthetic_Raw!AC15=1),"VETO","OK") | K14: =IF(J14="VETO","Macro / vol caution","Normal watch")
A15: =Synthetic_Raw!A16 | B15: =Synthetic_Raw!O16-Synthetic_Raw!M16 | C15: =(Synthetic_Raw!N16/Synthetic_Raw!M16)-1 | D15: =Synthetic_Raw!Q16-Synthetic_Raw!R16 | E15: =Synthetic_Raw!Q16-Synthetic_Raw!Q15 | F15: =(Synthetic_Raw!S16/Synthetic_Raw!S15)-1 | G15: =0.4*(B15/10)+0.3*C15+0.3*(Synthetic_Raw!M16/20) | H15: =(Synthetic_Raw!P16-135)/20 | I15: =0.35*G15+0.35*(ABS(E15)/25)+0.30*ABS(F15) | J15: =IF(OR(G15>0.85,I15>0.75,Synthetic_Raw!AC16=1),"VETO","OK") | K15: =IF(J15="VETO","Macro / vol caution","Normal watch")

Sheet Derived_Execution_Options
A1: Derived State: Execution & Options Pressure
A3: Date | B3: Range_Pct | C3: Rel_Volume | D3: Gamma_Pressure | E3: Flow_Bias | F3: IV_vs_RV | G3: Term_Stress | H3: Skew_Stress | I3: Dealer_Destab | J3: Squeeze_Proxy | K3: Pin_Risk_Proxy | L3: Execution_Context | M3: Comment
A4: =Synthetic_Raw!A5 | B4: =(Synthetic_Raw!C5-Synthetic_Raw!D5)/Synthetic_Raw!B5 | C4: =Synthetic_Raw!E5/AVERAGE(Synthetic_Raw!$E$5:Synthetic_Raw!E5) | D4: =Synthetic_Raw!W5*Synthetic_Raw!X5 | E4: =Synthetic_Raw!AB5 | F4: =Synthetic_Raw!Y5-Synthetic_Raw!AC5 | G4: =Synthetic_Raw!Z5 | H4: =Synthetic_Raw!AA5 | I4: =-1*Synthetic_Raw!W5 | J4: =0.30*I4+0.25*D4+0.20*E4+0.15*F4+0.10*C4 | K4: =0.50*ABS(D4)+0.30*Synthetic_Raw!X5+0.20*ABS(G4) | L4: =0.35*C4+0.20*(1-ABS(B4-0.08))+0.25*MAX(0,J4)+0.20*(1-MIN(1,ABS(Synthetic_Raw!AC5))) | M4: =IF(J4>0.35,"Possible squeeze regime",IF(K4>0.45,"Pin / strike gravity risk","Normal execution state"))
A5: =Synthetic_Raw!A6 | B5: =(Synthetic_Raw!C6-Synthetic_Raw!D6)/Synthetic_Raw!B6 | C5: =Synthetic_Raw!E6/AVERAGE(Synthetic_Raw!$E$5:Synthetic_Raw!E6) | D5: =Synthetic_Raw!W6*Synthetic_Raw!X6 | E5: =Synthetic_Raw!AB6 | F5: =Synthetic_Raw!Y6-Synthetic_Raw!AC6 | G5: =Synthetic_Raw!Z6 | H5: =Synthetic_Raw!AA6 | I5: =-1*Synthetic_Raw!W6 | J5: =0.30*I5+0.25*D5+0.20*E5+0.15*F5+0.10*C5 | K5: =0.50*ABS(D5)+0.30*Synthetic_Raw!X6+0.20*ABS(G5) | L5: =0.35*C5+0.20*(1-ABS(B5-0.08))+0.25*MAX(0,J5)+0.20*(1-MIN(1,ABS(Synthetic_Raw!AC6))) | M5: =IF(J5>0.35,"Possible squeeze regime",IF(K5>0.45,"Pin / strike gravity risk","Normal execution state"))
A6: =Synthetic_Raw!A7 | B6: =(Synthetic_Raw!C7-Synthetic_Raw!D7)/Synthetic_Raw!B7 | C6: =Synthetic_Raw!E7/AVERAGE(Synthetic_Raw!$E$5:Synthetic_Raw!E7) | D6: =Synthetic_Raw!W7*Synthetic_Raw!X7 | E6: =Synthetic_Raw!AB7 | F6: =Synthetic_Raw!Y7-Synthetic_Raw!AC7 | G6: =Synthetic_Raw!Z7 | H6: =Synthetic_Raw!AA7 | I6: =-1*Synthetic_Raw!W7 | J6: =0.30*I6+0.25*D6+0.20*E6+0.15*F6+0.10*C6 | K6: =0.50*ABS(D6)+0.30*Synthetic_Raw!X7+0.20*ABS(G6) | L6: =0.35*C6+0.20*(1-ABS(B6-0.08))+0.25*MAX(0,J6)+0.20*(1-MIN(1,ABS(Synthetic_Raw!AC7))) | M6: =IF(J6>0.35,"Possible squeeze regime",IF(K6>0.45,"Pin / strike gravity risk","Normal execution state"))
A7: =Synthetic_Raw!A8 | B7: =(Synthetic_Raw!C8-Synthetic_Raw!D8)/Synthetic_Raw!B8 | C7: =Synthetic_Raw!E8/AVERAGE(Synthetic_Raw!$E$5:Synthetic_Raw!E8) | D7: =Synthetic_Raw!W8*Synthetic_Raw!X8 | E7: =Synthetic_Raw!AB8 | F7: =Synthetic_Raw!Y8-Synthetic_Raw!AC8 | G7: =Synthetic_Raw!Z8 | H7: =Synthetic_Raw!AA8 | I7: =-1*Synthetic_Raw!W8 | J7: =0.30*I7+0.25*D7+0.20*E7+0.15*F7+0.10*C7 | K7: =0.50*ABS(D7)+0.30*Synthetic_Raw!X8+0.20*ABS(G7) | L7: =0.35*C7+0.20*(1-ABS(B7-0.08))+0.25*MAX(0,J7)+0.20*(1-MIN(1,ABS(Synthetic_Raw!AC8))) | M7: =IF(J7>0.35,"Possible squeeze regime",IF(K7>0.45,"Pin / strike gravity risk","Normal execution state"))
A8: =Synthetic_Raw!A9 | B8: =(Synthetic_Raw!C9-Synthetic_Raw!D9)/Synthetic_Raw!B9 | C8: =Synthetic_Raw!E9/AVERAGE(Synthetic_Raw!$E$5:Synthetic_Raw!E9) | D8: =Synthetic_Raw!W9*Synthetic_Raw!X9 | E8: =Synthetic_Raw!AB9 | F8: =Synthetic_Raw!Y9-Synthetic_Raw!AC9 | G8: =Synthetic_Raw!Z9 | H8: =Synthetic_Raw!AA9 | I8: =-1*Synthetic_Raw!W9 | J8: =0.30*I8+0.25*D8+0.20*E8+0.15*F8+0.10*C8 | K8: =0.50*ABS(D8)+0.30*Synthetic_Raw!X9+0.20*ABS(G8) | L8: =0.35*C8+0.20*(1-ABS(B8-0.08))+0.25*MAX(0,J8)+0.20*(1-MIN(1,ABS(Synthetic_Raw!AC9))) | M8: =IF(J8>0.35,"Possible squeeze regime",IF(K8>0.45,"Pin / strike gravity risk","Normal execution state"))
A9: =Synthetic_Raw!A10 | B9: =(Synthetic_Raw!C10-Synthetic_Raw!D10)/Synthetic_Raw!B10 | C9: =Synthetic_Raw!E10/AVERAGE(Synthetic_Raw!$E$5:Synthetic_Raw!E10) | D9: =Synthetic_Raw!W10*Synthetic_Raw!X10 | E9: =Synthetic_Raw!AB10 | F9: =Synthetic_Raw!Y10-Synthetic_Raw!AC10 | G9: =Synthetic_Raw!Z10 | H9: =Synthetic_Raw!AA10 | I9: =-1*Synthetic_Raw!W10 | J9: =0.30*I9+0.25*D9+0.20*E9+0.15*F9+0.10*C9 | K9: =0.50*ABS(D9)+0.30*Synthetic_Raw!X10+0.20*ABS(G9) | L9: =0.35*C9+0.20*(1-ABS(B9-0.08))+0.25*MAX(0,J9)+0.20*(1-MIN(1,ABS(Synthetic_Raw!AC10))) | M9: =IF(J9>0.35,"Possible squeeze regime",IF(K9>0.45,"Pin / strike gravity risk","Normal execution state"))
A10: =Synthetic_Raw!A11 | B10: =(Synthetic_Raw!C11-Synthetic_Raw!D11)/Synthetic_Raw!B11 | C10: =Synthetic_Raw!E11/AVERAGE(Synthetic_Raw!$E$5:Synthetic_Raw!E11) | D10: =Synthetic_Raw!W11*Synthetic_Raw!X11 | E10: =Synthetic_Raw!AB11 | F10: =Synthetic_Raw!Y11-Synthetic_Raw!AC11 | G10: =Synthetic_Raw!Z11 | H10: =Synthetic_Raw!AA11 | I10: =-1*Synthetic_Raw!W11 | J10: =0.30*I10+0.25*D10+0.20*E10+0.15*F10+0.10*C10 | K10: =0.50*ABS(D10)+0.30*Synthetic_Raw!X11+0.20*ABS(G10) | L10: =0.35*C10+0.20*(1-ABS(B10-0.08))+0.25*MAX(0,J10)+0.20*(1-MIN(1,ABS(Synthetic_Raw!AC11))) | M10: =IF(J10>0.35,"Possible squeeze regime",IF(K10>0.45,"Pin / strike gravity risk","Normal execution state"))
A11: =Synthetic_Raw!A12 | B11: =(Synthetic_Raw!C12-Synthetic_Raw!D12)/Synthetic_Raw!B12 | C11: =Synthetic_Raw!E12/AVERAGE(Synthetic_Raw!$E$5:Synthetic_Raw!E12) | D11: =Synthetic_Raw!W12*Synthetic_Raw!X12 | E11: =Synthetic_Raw!AB12 | F11: =Synthetic_Raw!Y12-Synthetic_Raw!AC12 | G11: =Synthetic_Raw!Z12 | H11: =Synthetic_Raw!AA12 | I11: =-1*Synthetic_Raw!W12 | J11: =0.30*I11+0.25*D11+0.20*E11+0.15*F11+0.10*C11 | K11: =0.50*ABS(D11)+0.30*Synthetic_Raw!X12+0.20*ABS(G11) | L11: =0.35*C11+0.20*(1-ABS(B11-0.08))+0.25*MAX(0,J11)+0.20*(1-MIN(1,ABS(Synthetic_Raw!AC12))) | M11: =IF(J11>0.35,"Possible squeeze regime",IF(K11>0.45,"Pin / strike gravity risk","Normal execution state"))
A12: =Synthetic_Raw!A13 | B12: =(Synthetic_Raw!C13-Synthetic_Raw!D13)/Synthetic_Raw!B13 | C12: =Synthetic_Raw!E13/AVERAGE(Synthetic_Raw!$E$5:Synthetic_Raw!E13) | D12: =Synthetic_Raw!W13*Synthetic_Raw!X13 | E12: =Synthetic_Raw!AB13 | F12: =Synthetic_Raw!Y13-Synthetic_Raw!AC13 | G12: =Synthetic_Raw!Z13 | H12: =Synthetic_Raw!AA13 | I12: =-1*Synthetic_Raw!W13 | J12: =0.30*I12+0.25*D12+0.20*E12+0.15*F12+0.10*C12 | K12: =0.50*ABS(D12)+0.30*Synthetic_Raw!X13+0.20*ABS(G12) | L12: =0.35*C12+0.20*(1-ABS(B12-0.08))+0.25*MAX(0,J12)+0.20*(1-MIN(1,ABS(Synthetic_Raw!AC13))) | M12: =IF(J12>0.35,"Possible squeeze regime",IF(K12>0.45,"Pin / strike gravity risk","Normal execution state"))
A13: =Synthetic_Raw!A14 | B13: =(Synthetic_Raw!C14-Synthetic_Raw!D14)/Synthetic_Raw!B14 | C13: =Synthetic_Raw!E14/AVERAGE(Synthetic_Raw!$E$5:Synthetic_Raw!E14) | D13: =Synthetic_Raw!W14*Synthetic_Raw!X14 | E13: =Synthetic_Raw!AB14 | F13: =Synthetic_Raw!Y14-Synthetic_Raw!AC14 | G13: =Synthetic_Raw!Z14 | H13: =Synthetic_Raw!AA14 | I13: =-1*Synthetic_Raw!W14 | J13: =0.30*I13+0.25*D13+0.20*E13+0.15*F13+0.10*C13 | K13: =0.50*ABS(D13)+0.30*Synthetic_Raw!X14+0.20*ABS(G13) | L13: =0.35*C13+0.20*(1-ABS(B13-0.08))+0.25*MAX(0,J13)+0.20*(1-MIN(1,ABS(Synthetic_Raw!AC14))) | M13: =IF(J13>0.35,"Possible squeeze regime",IF(K13>0.45,"Pin / strike gravity risk","Normal execution state"))
A14: =Synthetic_Raw!A15 | B14: =(Synthetic_Raw!C15-Synthetic_Raw!D15)/Synthetic_Raw!B15 | C14: =Synthetic_Raw!E15/AVERAGE(Synthetic_Raw!$E$5:Synthetic_Raw!E15) | D14: =Synthetic_Raw!W15*Synthetic_Raw!X15 | E14: =Synthetic_Raw!AB15 | F14: =Synthetic_Raw!Y15-Synthetic_Raw!AC15 | G14: =Synthetic_Raw!Z15 | H14: =Synthetic_Raw!AA15 | I14: =-1*Synthetic_Raw!W15 | J14: =0.30*I14+0.25*D14+0.20*E14+0.15*F14+0.10*C14 | K14: =0.50*ABS(D14)+0.30*Synthetic_Raw!X15+0.20*ABS(G14) | L14: =0.35*C14+0.20*(1-ABS(B14-0.08))+0.25*MAX(0,J14)+0.20*(1-MIN(1,ABS(Synthetic_Raw!AC15))) | M14: =IF(J14>0.35,"Possible squeeze regime",IF(K14>0.45,"Pin / strike gravity risk","Normal execution state"))
A15: =Synthetic_Raw!A16 | B15: =(Synthetic_Raw!C16-Synthetic_Raw!D16)/Synthetic_Raw!B16 | C15: =Synthetic_Raw!E16/AVERAGE(Synthetic_Raw!$E$5:Synthetic_Raw!E16) | D15: =Synthetic_Raw!W16*Synthetic_Raw!X16 | E15: =Synthetic_Raw!AB16 | F15: =Synthetic_Raw!Y16-Synthetic_Raw!AC16 | G15: =Synthetic_Raw!Z16 | H15: =Synthetic_Raw!AA16 | I15: =-1*Synthetic_Raw!W16 | J15: =0.30*I15+0.25*D15+0.20*E15+0.15*F15+0.10*C15 | K15: =0.50*ABS(D15)+0.30*Synthetic_Raw!X16+0.20*ABS(G15) | L15: =0.35*C15+0.20*(1-ABS(B15-0.08))+0.25*MAX(0,J15)+0.20*(1-MIN(1,ABS(Synthetic_Raw!AC16))) | M15: =IF(J15>0.35,"Possible squeeze regime",IF(K15>0.45,"Pin / strike gravity risk","Normal execution state"))

Sheet Derived_Asia_Breadth
A1: Derived State: Asia Handoff & Breadth
A3: Date | B3: NKY_Return | C3: HSI_Return | D3: HSTECH_Return | E3: Asia_Handoff_Score | F3: SPX_Breadth | G3: NDX_Breadth | H3: SOX_Breadth | I3: Concentration_Risk | J3: Comment
A4: =Synthetic_Raw!A5
A5: =Synthetic_Raw!A6 | B5: =(Synthetic_Raw!J6/Synthetic_Raw!J5)-1 | C5: =(Synthetic_Raw!K6/Synthetic_Raw!K5)-1 | D5: =(Synthetic_Raw!L6/Synthetic_Raw!L5)-1 | E5: =0.35*B5+0.30*C5+0.35*D5 | F5: =Synthetic_Raw!T6 | G5: =Synthetic_Raw!U6 | H5: =Synthetic_Raw!V6 | I5: =1-AVERAGE(F5:H5) | J5: =IF(E5>0.02,"Positive Asia handoff",IF(E5<-0.02,"Negative Asia handoff","Flat Asia handoff"))
A6: =Synthetic_Raw!A7 | B6: =(Synthetic_Raw!J7/Synthetic_Raw!J6)-1 | C6: =(Synthetic_Raw!K7/Synthetic_Raw!K6)-1 | D6: =(Synthetic_Raw!L7/Synthetic_Raw!L6)-1 | E6: =0.35*B6+0.30*C6+0.35*D6 | F6: =Synthetic_Raw!T7 | G6: =Synthetic_Raw!U7 | H6: =Synthetic_Raw!V7 | I6: =1-AVERAGE(F6:H6) | J6: =IF(E6>0.02,"Positive Asia handoff",IF(E6<-0.02,"Negative Asia handoff","Flat Asia handoff"))
A7: =Synthetic_Raw!A8 | B7: =(Synthetic_Raw!J8/Synthetic_Raw!J7)-1 | C7: =(Synthetic_Raw!K8/Synthetic_Raw!K7)-1 | D7: =(Synthetic_Raw!L8/Synthetic_Raw!L7)-1 | E7: =0.35*B7+0.30*C7+0.35*D7 | F7: =Synthetic_Raw!T8 | G7: =Synthetic_Raw!U8 | H7: =Synthetic_Raw!V8 | I7: =1-AVERAGE(F7:H7) | J7: =IF(E7>0.02,"Positive Asia handoff",IF(E7<-0.02,"Negative Asia handoff","Flat Asia handoff"))
A8: =Synthetic_Raw!A9 | B8: =(Synthetic_Raw!J9/Synthetic_Raw!J8)-1 | C8: =(Synthetic_Raw!K9/Synthetic_Raw!K8)-1 | D8: =(Synthetic_Raw!L9/Synthetic_Raw!L8)-1 | E8: =0.35*B8+0.30*C8+0.35*D8 | F8: =Synthetic_Raw!T9 | G8: =Synthetic_Raw!U9 | H8: =Synthetic_Raw!V9 | I8: =1-AVERAGE(F8:H8) | J8: =IF(E8>0.02,"Positive Asia handoff",IF(E8<-0.02,"Negative Asia handoff","Flat Asia handoff"))
A9: =Synthetic_Raw!A10 | B9: =(Synthetic_Raw!J10/Synthetic_Raw!J9)-1 | C9: =(Synthetic_Raw!K10/Synthetic_Raw!K9)-1 | D9: =(Synthetic_Raw!L10/Synthetic_Raw!L9)-1 | E9: =0.35*B9+0.30*C9+0.35*D9 | F9: =Synthetic_Raw!T10 | G9: =Synthetic_Raw!U10 | H9: =Synthetic_Raw!V10 | I9: =1-AVERAGE(F9:H9) | J9: =IF(E9>0.02,"Positive Asia handoff",IF(E9<-0.02,"Negative Asia handoff","Flat Asia handoff"))
A10: =Synthetic_Raw!A11 | B10: =(Synthetic_Raw!J11/Synthetic_Raw!J10)-1 | C10: =(Synthetic_Raw!K11/Synthetic_Raw!K10)-1 | D10: =(Synthetic_Raw!L11/Synthetic_Raw!L10)-1 | E10: =0.35*B10+0.30*C10+0.35*D10 | F10: =Synthetic_Raw!T11 | G10: =Synthetic_Raw!U11 | H10: =Synthetic_Raw!V11 | I10: =1-AVERAGE(F10:H10) | J10: =IF(E10>0.02,"Positive Asia handoff",IF(E10<-0.02,"Negative Asia handoff","Flat Asia handoff"))
A11: =Synthetic_Raw!A12 | B11: =(Synthetic_Raw!J12/Synthetic_Raw!J11)-1 | C11: =(Synthetic_Raw!K12/Synthetic_Raw!K11)-1 | D11: =(Synthetic_Raw!L12/Synthetic_Raw!L11)-1 | E11: =0.35*B11+0.30*C11+0.35*D11 | F11: =Synthetic_Raw!T12 | G11: =Synthetic_Raw!U12 | H11: =Synthetic_Raw!V12 | I11: =1-AVERAGE(F11:H11) | J11: =IF(E11>0.02,"Positive Asia handoff",IF(E11<-0.02,"Negative Asia handoff","Flat Asia handoff"))
A12: =Synthetic_Raw!A13 | B12: =(Synthetic_Raw!J13/Synthetic_Raw!J12)-1 | C12: =(Synthetic_Raw!K13/Synthetic_Raw!K12)-1 | D12: =(Synthetic_Raw!L13/Synthetic_Raw!L12)-1 | E12: =0.35*B12+0.30*C12+0.35*D12 | F12: =Synthetic_Raw!T13 | G12: =Synthetic_Raw!U13 | H12: =Synthetic_Raw!V13 | I12: =1-AVERAGE(F12:H12) | J12: =IF(E12>0.02,"Positive Asia handoff",IF(E12<-0.02,"Negative Asia handoff","Flat Asia handoff"))
A13: =Synthetic_Raw!A14 | B13: =(Synthetic_Raw!J14/Synthetic_Raw!J13)-1 | C13: =(Synthetic_Raw!K14/Synthetic_Raw!K13)-1 | D13: =(Synthetic_Raw!L14/Synthetic_Raw!L13)-1 | E13: =0.35*B13+0.30*C13+0.35*D13 | F13: =Synthetic_Raw!T14 | G13: =Synthetic_Raw!U14 | H13: =Synthetic_Raw!V14 | I13: =1-AVERAGE(F13:H13) | J13: =IF(E13>0.02,"Positive Asia handoff",IF(E13<-0.02,"Negative Asia handoff","Flat Asia handoff"))
A14: =Synthetic_Raw!A15 | B14: =(Synthetic_Raw!J15/Synthetic_Raw!J14)-1 | C14: =(Synthetic_Raw!K15/Synthetic_Raw!K14)-1 | D14: =(Synthetic_Raw!L15/Synthetic_Raw!L14)-1 | E14: =0.35*B14+0.30*C14+0.35*D14 | F14: =Synthetic_Raw!T15 | G14: =Synthetic_Raw!U15 | H14: =Synthetic_Raw!V15 | I14: =1-AVERAGE(F14:H14) | J14: =IF(E14>0.02,"Positive Asia handoff",IF(E14<-0.02,"Negative Asia handoff","Flat Asia handoff"))
A15: =Synthetic_Raw!A16 | B15: =(Synthetic_Raw!J16/Synthetic_Raw!J15)-1 | C15: =(Synthetic_Raw!K16/Synthetic_Raw!K15)-1 | D15: =(Synthetic_Raw!L16/Synthetic_Raw!L15)-1 | E15: =0.35*B15+0.30*C15+0.35*D15 | F15: =Synthetic_Raw!T16 | G15: =Synthetic_Raw!U16 | H15: =Synthetic_Raw!V16 | I15: =1-AVERAGE(F15:H15) | J15: =IF(E15>0.02,"Positive Asia handoff",IF(E15<-0.02,"Negative Asia handoff","Flat Asia handoff"))

Sheet Test_Use_Cases
A1: Test Use Cases & Expected Behaviour
A3: Scenario | B3: What it is testing | C3: Primary tabs to inspect | D3: Expected desk behaviour | E3: Likely vetoes | F3: Likely module interest | G3: Pass criterion
A4: Baseline | B4: Normal beta, moderate vol, neutral options pressure | C4: Derived_Beta_Leadership; Derived_Execution_Options | D4: Modules should behave normally without over-firing risk blocks | E4: Few / none | F4: Carry and SLV should both remain evaluable | G4: No accidental veto cascade
A5: Stress | B5: Rates up, vol up, weaker breadth, negative dealer gamma shift | C5: Derived_Vol_Rates_FX; Derived_Asia_Breadth | D5: Risk should de-gear, macro vetoes should appear, squeeze logic should not masquerade as opportunity | E5: Macro veto, weak breadth, execution caution | F5: Risk gateway and carry block logic | G5: Stress state clearly differentiated from baseline
A6: Squeeze | B6: Positive beta, semis leadership, positive flow imbalance, strong gamma concentration | C6: Derived_Execution_Options; Derived_Beta_Leadership | D6: Squeeze proxy should rise while breadth and leadership stay supportive | E6: Only if vol or event flag breaks thresholds | F6: SLV / event-driven squeeze testing | G6: Squeeze regime scores higher than baseline and stress

Sheet Temporal_Step1_Framework
A1: Temporal Step1 Framework — “Where are we now?”
A2: Purpose: define Step 1 as its own deterministic layer using calendar/clock plus primitive intraday observables only; no Step 2/3 leakage.
A4: Architecture guardrails | H4: Candidate threshold controls (editable blue inputs for workbook testing)
A5: Rule_ID | B5: Rule | C5: Why | D5: Dependency policy | E5: Practical consequence | F5: Status | H5: Threshold | I5: Value | J5: Meaning
A6: G01 | B6: Keep clock envelope separate from behavioural phase. | C6: The clock says what is plausible; the tape says what is actually happening. | D6: Allowed | E6: Preserve both fields in Step 1 outputs. | F6: Adopted | H6: open_disorder_relvol_min | I6: 1.4 | J6: RelVol threshold for unresolved open behaviour
A7: G02 | B7: Step 1 may consume only primitive observables. | C7: Prevents loops and double-counting. | D7: Allowed | E7: Use timestamps, price, volume, VWAP, opening range, realised vol, event/expiry timestamps. | F7: Adopted | H7: open_disorder_rv5_bps_min | I7: 80 | J7: 5-minute realised-vol threshold for open disorder
